

try:
    ass()
except Exception as err:
    print('um erro aconteceu: ', err)
